Workbook

Sheet Summary
A1: RBC Cloud Business Case Tracker
A2: Platform × capability coverage · Zephyr vs non-Zephyr split · September 25, 2026
A4: KEY METRICS
A5: Total platforms | B5: 88
A6: Platforms named | B6: =COUNTA(Platforms!A5:A30,Platforms!A32:A45,Platforms!A47:A62,Platforms!A64:A69,Platforms!A71:A73,Platforms!A75:A92,Platforms!A94,Platforms!A96:A99)
A7: Capabilities in scope | B7: =Platforms!AY100
A8: Capabilities with Zephyr decision | B8: =COUNTA(Platforms!D3:AX3)
A9: Overall % via Zephyr | B9: =Platforms!AZ100
A10: Overall % outside Zephyr | B10: =Platforms!BA100
A11: Overall % undecided | B11: =Platforms!BB100
A13: BY CATEGORY
A14: Category | B14: Platforms | C14: In scope | D14: % Zephyr | E14: % Non-Zephyr | F14: % Undecided
A15: Application | B15: 26 | C15: =Platforms!AY4 | D15: =Platforms!AZ4 | E15: =Platforms!BA4 | F15: =Platforms!BB4
A16: Connectivity | B16: 14 | C16: =Platforms!AY31 | D16: =Platforms!AZ31 | E16: =Platforms!BA31 | F16: =Platforms!BB31
A17: Data | B17: 16 | C17: =Platforms!AY46 | D17: =Platforms!AZ46 | E17: =Platforms!BA46 | F17: =Platforms!BB46
A18: Storage | B18: 6 | C18: =Platforms!AY63 | D18: =Platforms!AZ63 | E18: =Platforms!BA63 | F18: =Platforms!BB63
A19: Operations | B19: 3 | C19: =Platforms!AY70 | D19: =Platforms!AZ70 | E19: =Platforms!BA70 | F19: =Platforms!BB70
A20: Compute | B20: 18 | C20: =Platforms!AY74 | D20: =Platforms!AZ74 | E20: =Platforms!BA74 | F20: =Platforms!BB74
A21: Client Computing | B21: 1 | C21: =Platforms!AY93 | D21: =Platforms!AZ93 | E21: =Platforms!BA93 | F21: =Platforms!BB93
A22: Mainframe | B22: 4 | C22: =Platforms!AY95 | D22: =Platforms!AZ95 | E22: =Platforms!BA95 | F22: =Platforms!BB95
A24: How to use: set each capability's Zephyr decision on the Platforms helper row, mark Yes / No / TBD per platform, and the splits roll up automatically. Planned next: hours-saved tracking (Before / After Zephyr hours).

Sheet Platforms
A1: Platform Details | D1: Onboarding | F1: Provisioning | T1: Management | AE1: Optimization | AK1: Compliance | AL1: Lifecycle | AQ1: Security | AU1: Observability | AY1: Total | AZ1: Zephyr vs Non-Zephyr
A2: Platform Name | B2: Service Name | C2: Rollout Status | D2: Onboarding Consultations | E2: Onboarding Approvals | F2: Procure Infras | G2: Rack and Stack in DC | H2: Provision OS | I2: Request Access (AD or Sudo) | J2: Virtual Compute Provisioning | K2: Software Install (DB, Middleware etc) | L2: Backups | M2: Vulnerability (Find latest version) | N2: TSS Hardening | O2: Encryption | P2: Logging/Auditing | Q2: Resource Tagging | R2: Activity Monitoring | S2: ITAM Onboarding | T2: ITAM Reconciliation | U2: DR Failover & Validation | V2: Healthchecks | W2: Version/EoL Upgrades | X2: DR Tests (Graceful Failover) | Y2: TSS Reporting | Z2: Vulnerability Patching | AA2: Restore Tests | AB2: IAM Attestations | AC2: Process Documentation | AD2: Migrations | AE2: Observability | AF2: Utilization Reports | AG2: Metrics Collection | AH2: Right Sizing & Auto Scaling | AI2: Eliminate redundant platforms | AJ2: FinOps Optimization | AK2: Centralized Compliance Visibility | AL2: Provisioning | AM2: Patch Execution | AN2: Scaling | AO2: Decommissioning | AP2: Backup & Restores | AQ2: IAM / PAM | AR2: Encryption Standards | AS2: Encryption (TDS/Imperva) | AT2: Secrets Mgmt | AU2: Monitoring | AV2: Logging | AW2: Distributed Tracing | AX2: Alerting | AY2: In scope | AZ2: % via Zephyr | BA2: % outside Zephyr | BB2: % undecided
A3: Zephyr decision →
A4: Application (26 platforms) | AY4: =SUM(AY5:AY30) | AZ4: =IF($AY4=0,"",SUMPRODUCT($AZ5:$AZ30,$AY5:$AY30)/$AY4) | BA4: =IF($AY4=0,"",SUMPRODUCT($BA5:$BA30,$AY5:$AY30)/$AY4) | BB4: =IF($AY4=0,"",1-$AZ4-$BA4)
AY5: =COUNTIF(D5:AX5,"Yes") | AZ5: =IF($AY5=0,"",SUMPRODUCT(($D5:$AX5="Yes")*($D$3:$AX$3="Expose via Zephyr"))/$AY5) | BA5: =IF($AY5=0,"",SUMPRODUCT(($D5:$AX5="Yes")*($D$3:$AX$3="Deliver outside Zephyr"))/$AY5) | BB5: =IF($AY5=0,"",1-$AZ5-$BA5)
AY6: =COUNTIF(D6:AX6,"Yes") | AZ6: =IF($AY6=0,"",SUMPRODUCT(($D6:$AX6="Yes")*($D$3:$AX$3="Expose via Zephyr"))/$AY6) | BA6: =IF($AY6=0,"",SUMPRODUCT(($D6:$AX6="Yes")*($D$3:$AX$3="Deliver outside Zephyr"))/$AY6) | BB6: =IF($AY6=0,"",1-$AZ6-$BA6)
AY7: =COUNTIF(D7:AX7,"Yes") | AZ7: =IF($AY7=0,"",SUMPRODUCT(($D7:$AX7="Yes")*($D$3:$AX$3="Expose via Zephyr"))/$AY7) | BA7: =IF($AY7=0,"",SUMPRODUCT(($D7:$AX7="Yes")*($D$3:$AX$3="Deliver outside Zephyr"))/$AY7) | BB7: =IF($AY7=0,"",1-$AZ7-$BA7)
AY8: =COUNTIF(D8:AX8,"Yes") | AZ8: =IF($AY8=0,"",SUMPRODUCT(($D8:$AX8="Yes")*($D$3:$AX$3="Expose via Zephyr"))/$AY8) | BA8: =IF($AY8=0,"",SUMPRODUCT(($D8:$AX8="Yes")*($D$3:$AX$3="Deliver outside Zephyr"))/$AY8) | BB8: =IF($AY8=0,"",1-$AZ8-$BA8)
AY9: =COUNTIF(D9:AX9,"Yes") | AZ9: =IF($AY9=0,"",SUMPRODUCT(($D9:$AX9="Yes")*($D$3:$AX$3="Expose via Zephyr"))/$AY9) | BA9: =IF($AY9=0,"",SUMPRODUCT(($D9:$AX9="Yes")*($D$3:$AX$3="Deliver outside Zephyr"))/$AY9) | BB9: =IF($AY9=0,"",1-$AZ9-$BA9)
AY10: =COUNTIF(D10:AX10,"Yes") | AZ10: =IF($AY10=0,"",SUMPRODUCT(($D10:$AX10="Yes")*($D$3:$AX$3="Expose via Zephyr"))/$AY10) | BA10: =IF($AY10=0,"",SUMPRODUCT(($D10:$AX10="Yes")*($D$3:$AX$3="Deliver outside Zephyr"))/$AY10) | BB10: =IF($AY10=0,"",1-$AZ10-$BA10)
AY11: =COUNTIF(D11:AX11,"Yes") | AZ11: =IF($AY11=0,"",SUMPRODUCT(($D11:$AX11="Yes")*($D$3:$AX$3="Expose via Zephyr"))/$AY11) | BA11: =IF($AY11=0,"",SUMPRODUCT(($D11:$AX11="Yes")*($D$3:$AX$3="Deliver outside Zephyr"))/$AY11) | BB11: =IF($AY11=0,"",1-$AZ11-$BA11)
AY12: =COUNTIF(D12:AX12,"Yes") | AZ12: =IF($AY12=0,"",SUMPRODUCT(($D12:$AX12="Yes")*($D$3:$AX$3="Expose via Zephyr"))/$AY12) | BA12: =IF($AY12=0,"",SUMPRODUCT(($D12:$AX12="Yes")*($D$3:$AX$3="Deliver outside Zephyr"))/$AY12) | BB12: =IF($AY12=0,"",1-$AZ12-$BA12)
AY13: =COUNTIF(D13:AX13,"Yes") | AZ13: =IF($AY13=0,"",SUMPRODUCT(($D13:$AX13="Yes")*($D$3:$AX$3="Expose via Zephyr"))/$AY13) | BA13: =IF($AY13=0,"",SUMPRODUCT(($D13:$AX13="Yes")*($D$3:$AX$3="Deliver outside Zephyr"))/$AY13) | BB13: =IF($AY13=0,"",1-$AZ13-$BA13)
AY14: =COUNTIF(D14:AX14,"Yes") | AZ14: =IF($AY14=0,"",SUMPRODUCT(($D14:$AX14="Yes")*($D$3:$AX$3="Expose via Zephyr"))/$AY14) | BA14: =IF($AY14=0,"",SUMPRODUCT(($D14:$AX14="Yes")*($D$3:$AX$3="Deliver outside Zephyr"))/$AY14) | BB14: =IF($AY14=0,"",1-$AZ14-$BA14)
AY15: =COUNTIF(D15:AX15,"Yes") | AZ15: =IF($AY15=0,"",SUMPRODUCT(($D15:$AX15="Yes")*($D$3:$AX$3="Expose via Zephyr"))/$AY15) | BA15: =IF($AY15=0,"",SUMPRODUCT(($D15:$AX15="Yes")*($D$3:$AX$3="Deliver outside Zephyr"))/$AY15) | BB15: =IF($AY15=0,"",1-$AZ15-$BA15)
AY16: =COUNTIF(D16:AX16,"Yes") | AZ16: =IF($AY16=0,"",SUMPRODUCT(($D16:$AX16="Yes")*($D$3:$AX$3="Expose via Zephyr"))/$AY16) | BA16: =IF($AY16=0,"",SUMPRODUCT(($D16:$AX16="Yes")*($D$3:$AX$3="Deliver outside Zephyr"))/$AY16) | BB16: =IF($AY16=0,"",1-$AZ16-$BA16)
... AY30: =COUNTIF(D30:AX30,"Yes") | AZ30: =IF($AY30=0,"",SUMPRODUCT(($D30:$AX30="Yes")*($D$3:$AX$3="Expose via Zephyr"))/$AY30) | BA30: =IF($AY30=0,"",SUMPRODUCT(($D30:$AX30="Yes")*($D$3:$AX$3="Deliver outside Zephyr"))/$AY30) | BB30: =IF($AY30=0,"",1-$AZ30-$BA30)
A31: Connectivity (14 platforms) | AY31: =SUM(AY32:AY45) | AZ31: =IF($AY31=0,"",SUMPRODUCT($AZ32:$AZ45,$AY32:$AY45)/$AY31) | BA31: =IF($AY31=0,"",SUMPRODUCT($BA32:$BA45,$AY32:$AY45)/$AY31) | BB31: =IF($AY31=0,"",1-$AZ31-$BA31)
AY32: =COUNTIF(D32:AX32,"Yes") | AZ32: =IF($AY32=0,"",SUMPRODUCT(($D32:$AX32="Yes")*($D$3:$AX$3="Expose via Zephyr"))/$AY32) | BA32: =IF($AY32=0,"",SUMPRODUCT(($D32:$AX32="Yes")*($D$3:$AX$3="Deliver outside Zephyr"))/$AY32) | BB32: =IF($AY32=0,"",1-$AZ32-$BA32)
AY33: =COUNTIF(D33:AX33,"Yes") | AZ33: =IF($AY33=0,"",SUMPRODUCT(($D33:$AX33="Yes")*($D$3:$AX$3="Expose via Zephyr"))/$AY33) | BA33: =IF($AY33=0,"",SUMPRODUCT(($D33:$AX33="Yes")*($D$3:$AX$3="Deliver outside Zephyr"))/$AY33) | BB33: =IF($AY33=0,"",1-$AZ33-$BA33)
AY34: =COUNTIF(D34:AX34,"Yes") | AZ34: =IF($AY34=0,"",SUMPRODUCT(($D34:$AX34="Yes")*($D$3:$AX$3="Expose via Zephyr"))/$AY34) | BA34: =IF($AY34=0,"",SUMPRODUCT(($D34:$AX34="Yes")*($D$3:$AX$3="Deliver outside Zephyr"))/$AY34) | BB34: =IF($AY34=0,"",1-$AZ34-$BA34)
AY35: =COUNTIF(D35:AX35,"Yes") | AZ35: =IF($AY35=0,"",SUMPRODUCT(($D35:$AX35="Yes")*($D$3:$AX$3="Expose via Zephyr"))/$AY35) | BA35: =IF($AY35=0,"",SUMPRODUCT(($D35:$AX35="Yes")*($D$3:$AX$3="Deliver outside Zephyr"))/$AY35) | BB35: =IF($AY35=0,"",1-$AZ35-$BA35)
AY36: =COUNTIF(D36:AX36,"Yes") | AZ36: =IF($AY36=0,"",SUMPRODUCT(($D36:$AX36="Yes")*($D$3:$AX$3="Expose via Zephyr"))/$AY36) | BA36: =IF($AY36=0,"",SUMPRODUCT(($D36:$AX36="Yes")*($D$3:$AX$3="Deliver outside Zephyr"))/$AY36) | BB36: =IF($AY36=0,"",1-$AZ36-$BA36)
AY37: =COUNTIF(D37:AX37,"Yes") | AZ37: =IF($AY37=0,"",SUMPRODUCT(($D37:$AX37="Yes")*($D$3:$AX$3="Expose via Zephyr"))/$AY37) | BA37: =IF($AY37=0,"",SUMPRODUCT(($D37:$AX37="Yes")*($D$3:$AX$3="Deliver outside Zephyr"))/$AY37) | BB37: =IF($AY37=0,"",1-$AZ37-$BA37)
AY38: =COUNTIF(D38:AX38,"Yes") | AZ38: =IF($AY38=0,"",SUMPRODUCT(($D38:$AX38="Yes")*($D$3:$AX$3="Expose via Zephyr"))/$AY38) | BA38: =IF($AY38=0,"",SUMPRODUCT(($D38:$AX38="Yes")*($D$3:$AX$3="Deliver outside Zephyr"))/$AY38) | BB38: =IF($AY38=0,"",1-$AZ38-$BA38)
AY39: =COUNTIF(D39:AX39,"Yes") | AZ39: =IF($AY39=0,"",SUMPRODUCT(($D39:$AX39="Yes")*($D$3:$AX$3="Expose via Zephyr"))/$AY39) | BA39: =IF($AY39=0,"",SUMPRODUCT(($D39:$AX39="Yes")*($D$3:$AX$3="Deliver outside Zephyr"))/$AY39) | BB39: =IF($AY39=0,"",1-$AZ39-$BA39)
AY40: =COUNTIF(D40:AX40,"Yes") | AZ40: =IF($AY40=0,"",SUMPRODUCT(($D40:$AX40="Yes")*($D$3:$AX$3="Expose via Zephyr"))/$AY40) | BA40: =IF($AY40=0,"",SUMPRODUCT(($D40:$AX40="Yes")*($D$3:$AX$3="Deliver outside Zephyr"))/$AY40) | BB40: =IF($AY40=0,"",1-$AZ40-$BA40)
AY41: =COUNTIF(D41:AX41,"Yes") | AZ41: =IF($AY41=0,"",SUMPRODUCT(($D41:$AX41="Yes")*($D$3:$AX$3="Expose via Zephyr"))/$AY41) | BA41: =IF($AY41=0,"",SUMPRODUCT(($D41:$AX41="Yes")*($D$3:$AX$3="Deliver outside Zephyr"))/$AY41) | BB41: =IF($AY41=0,"",1-$AZ41-$BA41)
AY42: =COUNTIF(D42:AX42,"Yes") | AZ42: =IF($AY42=0,"",SUMPRODUCT(($D42:$AX42="Yes")*($D$3:$AX$3="Expose via Zephyr"))/$AY42) | BA42: =IF($AY42=0,"",SUMPRODUCT(($D42:$AX42="Yes")*($D$3:$AX$3="Deliver outside Zephyr"))/$AY42) | BB42: =IF($AY42=0,"",1-$AZ42-$BA42)
AY43: =COUNTIF(D43:AX43,"Yes") | AZ43: =IF($AY43=0,"",SUMPRODUCT(($D43:$AX43="Yes")*($D$3:$AX$3="Expose via Zephyr"))/$AY43) | BA43: =IF($AY43=0,"",SUMPRODUCT(($D43:$AX43="Yes")*($D$3:$AX$3="Deliver outside Zephyr"))/$AY43) | BB43: =IF($AY43=0,"",1-$AZ43-$BA43)
... AY45: =COUNTIF(D45:AX45,"Yes") | AZ45: =IF($AY45=0,"",SUMPRODUCT(($D45:$AX45="Yes")*($D$3:$AX$3="Expose via Zephyr"))/$AY45) | BA45: =IF($AY45=0,"",SUMPRODUCT(($D45:$AX45="Yes")*($D$3:$AX$3="Deliver outside Zephyr"))/$AY45) | BB45: =IF($AY45=0,"",1-$AZ45-$BA45)
A46: Data (16 platforms) | AY46: =SUM(AY47:AY62) | AZ46: =IF($AY46=0,"",SUMPRODUCT($AZ47:$AZ62,$AY47:$AY62)/$AY46) | BA46: =IF($AY46=0,"",SUMPRODUCT($BA47:$BA62,$AY47:$AY62)/$AY46) | BB46: =IF($AY46=0,"",1-$AZ46-$BA46)
AY47: =COUNTIF(D47:AX47,"Yes") | AZ47: =IF($AY47=0,"",SUMPRODUCT(($D47:$AX47="Yes")*($D$3:$AX$3="Expose via Zephyr"))/$AY47) | BA47: =IF($AY47=0,"",SUMPRODUCT(($D47:$AX47="Yes")*($D$3:$AX$3="Deliver outside Zephyr"))/$AY47) | BB47: =IF($AY47=0,"",1-$AZ47-$BA47)
AY48: =COUNTIF(D48:AX48,"Yes") | AZ48: =IF($AY48=0,"",SUMPRODUCT(($D48:$AX48="Yes")*($D$3:$AX$3="Expose via Zephyr"))/$AY48) | BA48: =IF($AY48=0,"",SUMPRODUCT(($D48:$AX48="Yes")*($D$3:$AX$3="Deliver outside Zephyr"))/$AY48) | BB48: =IF($AY48=0,"",1-$AZ48-$BA48)
AY49: =COUNTIF(D49:AX49,"Yes") | AZ49: =IF($AY49=0,"",SUMPRODUCT(($D49:$AX49="Yes")*($D$3:$AX$3="Expose via Zephyr"))/$AY49) | BA49: =IF($AY49=0,"",SUMPRODUCT(($D49:$AX49="Yes")*($D$3:$AX$3="Deliver outside Zephyr"))/$AY49) | BB49: =IF($AY49=0,"",1-$AZ49-$BA49)
AY50: =COUNTIF(D50:AX50,"Yes") | AZ50: =IF($AY50=0,"",SUMPRODUCT(($D50:$AX50="Yes")*($D$3:$AX$3="Expose via Zephyr"))/$AY50) | BA50: =IF($AY50=0,"",SUMPRODUCT(($D50:$AX50="Yes")*($D$3:$AX$3="Deliver outside Zephyr"))/$AY50) | BB50: =IF($AY50=0,"",1-$AZ50-$BA50)
AY51: =COUNTIF(D51:AX51,"Yes") | AZ51: =IF($AY51=0,"",SUMPRODUCT(($D51:$AX51="Yes")*($D$3:$AX$3="Expose via Zephyr"))/$AY51) | BA51: =IF($AY51=0,"",SUMPRODUCT(($D51:$AX51="Yes")*($D$3:$AX$3="Deliver outside Zephyr"))/$AY51) | BB51: =IF($AY51=0,"",1-$AZ51-$BA51)
AY52: =COUNTIF(D52:AX52,"Yes") | AZ52: =IF($AY52=0,"",SUMPRODUCT(($D52:$AX52="Yes")*($D$3:$AX$3="Expose via Zephyr"))/$AY52) | BA52: =IF($AY52=0,"",SUMPRODUCT(($D52:$AX52="Yes")*($D$3:$AX$3="Deliver outside Zephyr"))/$AY52) | BB52: =IF($AY52=0,"",1-$AZ52-$BA52)
AY53: =COUNTIF(D53:AX53,"Yes") | AZ53: =IF($AY53=0,"",SUMPRODUCT(($D53:$AX53="Yes")*($D$3:$AX$3="Expose via Zephyr"))/$AY53) | BA53: =IF($AY53=0,"",SUMPRODUCT(($D53:$AX53="Yes")*($D$3:$AX$3="Deliver outside Zephyr"))/$AY53) | BB53: =IF($AY53=0,"",1-$AZ53-$BA53)
AY54: =COUNTIF(D54:AX54,"Yes") | AZ54: =IF($AY54=0,"",SUMPRODUCT(($D54:$AX54="Yes")*($D$3:$AX$3="Expose via Zephyr"))/$AY54) | BA54: =IF($AY54=0,"",SUMPRODUCT(($D54:$AX54="Yes")*($D$3:$AX$3="Deliver outside Zephyr"))/$AY54) | BB54: =IF($AY54=0,"",1-$AZ54-$BA54)
...

Sheet Legend
A1: Area | B1: Value | C1: What it means
A2: ZEPHYR DECISION (set on the Platforms helper row, one per capability)
A3: Zephyr decision | B3: Expose via Zephyr | C3: Capability is exposed to consumers through Zephyr (catalog / Add to Solution). Counts toward % via Zephyr.
B4: Deliver outside Zephyr | C4: RBC Cloud delivers without Zephyr involvement. Counts toward % outside Zephyr.
B5: Defer | C5: Valid need, but not for 2027. Counts as undecided for now.
B6: Park | C6: No 2027 value. Counts as undecided for now.
B7: TBD / blank | C7: Not yet decided. Counts as undecided.
A8: PLATFORMS TAB
A9: Platforms tab | B9: Yes / No / TBD | C9: Whether the capability applies to that platform: Yes = in scope, No = not applicable, TBD = not yet assessed.
B10: Rollout Status | C10: Platform rollout state: Not Started / In Progress / Complete / TBD.
B11: In scope | C11: Per platform: count of capabilities marked Yes. Category headers and the portfolio total sum automatically.
B12: % via Zephyr / % outside / % undecided | C12: Share of in-scope capabilities by Zephyr decision. Updates automatically when decisions are set on the helper row.
B13: Collapsible groups | C13: Use the +/- outline buttons on the left edge to collapse or expand each platform category.
B14: Planned | C14: Hours-saved tracking (Before / After Zephyr hours) — to be added.
B15: 47 capability columns | C15: 34 operational activities from the Zephyr Efficiency analysis + 13 HOM capabilities (Lifecycle: Provisioning, Patch Execution, Scaling, Decommissioning, Backup & Restores; Security: IAM/PAM, Encryption Standards, TDS/Imperva, Secrets Mgmt; Observability: Monitoring, Logging, Distributed Tracing, Alerting).
